<?xml version="1.0" ?>
<robot name="prjct_spider_bot" xmlns:xacro="http://www.ros.org/wiki/xacro">

  <xacro:arg name="use_ros2_control" default="false"/>

<xacro:include filename="$(find prjct_spider_bot_description)/urdf/materials.xacro" />
<xacro:if value="$(arg use_ros2_control)">
  <xacro:include filename="$(find prjct_spider_bot_description)/urdf/prjct_spider_bot.ros2control.xml" />
</xacro:if>
<xacro:include filename="$(find prjct_spider_bot_description)/urdf/prjct_spider_bot.gazebo" />
<link name="base_link">
  <inertial>
    <origin xyz="-0.011634383299055345 -0.020012327327441907 0.04021488449284461" rpy="0 0 0"/>
    <mass value="5.582430267110478"/>
    <inertia ixx="0.022303" iyy="0.019413" izz="0.030673" ixy="-6e-06" iyz="4e-06" ixz="0.000124"/>
  </inertial>
  <visual>
    <origin xyz="0 0 0" rpy="0 0 0"/>
    <geometry>
      <mesh filename="file://$(find prjct_spider_bot_description)/meshes/base_link.stl" scale="0.001 0.001 0.001"/>
    </geometry>
    <material name="silver"/>
  </visual>
  <collision>
    <origin xyz="0 0 0" rpy="0 0 0"/>
    <geometry>
      <mesh filename="file://$(find prjct_spider_bot_description)/meshes/base_link.stl" scale="0.001 0.001 0.001"/>
    </geometry>
  </collision>
</link>

<link name="lidar_1">
  <inertial>
    <origin xyz="1.1999484417213324e-07 7.555305850739935e-08 0.009521070328133499" rpy="0 0 0"/>
    <mass value="0.6521818172175858"/>
    <inertia ixx="0.000253" iyy="0.000253" izz="0.000465" ixy="-0.0" iyz="-0.0" ixz="-0.0"/>
  </inertial>
  <visual>
    <origin xyz="0.069407 0.019459 -0.0877" rpy="0 0 0"/>
    <geometry>
      <mesh filename="file://$(find prjct_spider_bot_description)/meshes/lidar_1.stl" scale="0.001 0.001 0.001"/>
    </geometry>
    <material name="silver"/>
  </visual>
  <collision>
    <origin xyz="0.069407 0.019459 -0.0877" rpy="0 0 0"/>
    <geometry>
      <mesh filename="file://$(find prjct_spider_bot_description)/meshes/lidar_1.stl" scale="0.001 0.001 0.001"/>
    </geometry>
  </collision>
</link>

<link name="imu_1">
  <inertial>
    <origin xyz="6.730727086790012e-16 -4.6485218993877475e-07 0.002500000000000016" rpy="0 0 0"/>
    <mass value="0.047099999999999996"/>
    <inertia ixx="6e-06" iyy="4e-06" izz="1e-05" ixy="0.0" iyz="-0.0" ixz="0.0"/>
  </inertial>
  <visual>
    <origin xyz="-0.01 0.02 -0.0877" rpy="0 0 0"/>
    <geometry>
      <mesh filename="file://$(find prjct_spider_bot_description)/meshes/imu_1.stl" scale="0.001 0.001 0.001"/>
    </geometry>
    <material name="silver"/>
  </visual>
  <collision>
    <origin xyz="-0.01 0.02 -0.0877" rpy="0 0 0"/>
    <geometry>
      <mesh filename="file://$(find prjct_spider_bot_description)/meshes/imu_1.stl" scale="0.001 0.001 0.001"/>
    </geometry>
  </collision>
</link>

<link name="camera_stand_1">
  <inertial>
    <origin xyz="0.002322519957098118 -4.6855707672502356e-07 0.039074935332732846" rpy="0 0 0"/>
    <mass value="0.28621405783156734"/>
    <inertia ixx="0.000356" iyy="0.000274" izz="0.000106" ixy="-0.0" iyz="-0.0" ixz="-0.0"/>
  </inertial>
  <visual>
    <origin xyz="-0.064 0.02 -0.0877" rpy="0 0 0"/>
    <geometry>
      <mesh filename="file://$(find prjct_spider_bot_description)/meshes/camera_stand_1.stl" scale="0.001 0.001 0.001"/>
    </geometry>
    <material name="silver"/>
  </visual>
  <collision>
    <origin xyz="-0.064 0.02 -0.0877" rpy="0 0 0"/>
    <geometry>
      <mesh filename="file://$(find prjct_spider_bot_description)/meshes/camera_stand_1.stl" scale="0.001 0.001 0.001"/>
    </geometry>
  </collision>
</link>

<link name="camera_1">
  <inertial>
    <origin xyz="0.0008434977883624573 5.831530578740904e-05 0.013851911513465182" rpy="0 0 0"/>
    <mass value="0.04133715258262728"/>
    <inertia ixx="4.5e-05" iyy="8e-06" izz="4.5e-05" ixy="0.0" iyz="0.0" ixz="-0.0"/>
  </inertial>
  <visual>
    <origin xyz="-0.061225 0.02 -0.1647" rpy="0 0 0"/>
    <geometry>
      <mesh filename="file://$(find prjct_spider_bot_description)/meshes/camera_1.stl" scale="0.001 0.001 0.001"/>
    </geometry>
    <material name="silver"/>
  </visual>
  <collision>
    <origin xyz="-0.061225 0.02 -0.1647" rpy="0 0 0"/>
    <geometry>
      <mesh filename="file://$(find prjct_spider_bot_description)/meshes/camera_1.stl" scale="0.001 0.001 0.001"/>
    </geometry>
  </collision>
</link>
<!-- === Locked sensor mount frames (aliases) === -->
<link name="lidar_link"/>
<link name="camera_link"/>
<link name="camera_optical_frame"/>

<joint name="J_lidar_alias" type="fixed">
  <parent link="lidar_1"/>
  <child link="lidar_link"/>
  <origin xyz="0 0 0" rpy="0 0 0"/>
</joint>

<joint name="J_camera_alias" type="fixed">
  <parent link="camera_1"/>
  <child link="camera_link"/>
  <origin xyz="0 0 0" rpy="0 0 0"/>
</joint>

<!-- REP-103 optical frame: X right, Y down, Z forward -->
<joint name="J_camera_optical" type="fixed">
  <parent link="camera_link"/>
  <child link="camera_optical_frame"/>
  <origin xyz="0 0 0" rpy="-1.57079632679 0 -1.57079632679"/>
</joint>


<link name="coxa_FR_1">
  <inertial>
    <origin xyz="-0.028011122462089755 0.02918946766406348 -0.02516145237879074" rpy="0 0 0"/>
    <mass value="0.5326447248518721"/>
    <inertia ixx="0.00026" iyy="0.000276" izz="0.000188" ixy="2.9e-05" iyz="-1e-05" ixz="-2e-06"/>
  </inertial>
  <visual>
    <origin xyz="0.0749 -0.0542 -0.0528" rpy="0 0 0"/>
    <geometry>
      <mesh filename="file://$(find prjct_spider_bot_description)/meshes/coxa_FR_1.stl" scale="0.001 0.001 0.001"/>
    </geometry>
    <material name="silver"/>
  </visual>
  <collision>
    <origin xyz="0.0749 -0.0542 -0.0528" rpy="0 0 0"/>
    <geometry>
      <mesh filename="file://$(find prjct_spider_bot_description)/meshes/coxa_FR_1.stl" scale="0.001 0.001 0.001"/>
    </geometry>
  </collision>
</link>

<link name="femur_FR_1">
  <inertial>
    <origin xyz="-0.006558818685370449 0.04487966340235518 -0.0035371973943164325" rpy="0 0 0"/>
    <mass value="0.3037238401732045"/>
    <inertia ixx="0.000169" iyy="0.000169" izz="0.000293" ixy="-3.2e-05" iyz="1.9e-05" ixz="-1.9e-05"/>
  </inertial>
  <visual>
    <origin xyz="0.130196 -0.070181 -0.0387" rpy="0 0 0"/>
    <geometry>
      <mesh filename="file://$(find prjct_spider_bot_description)/meshes/femur_FR_1.stl" scale="0.001 0.001 0.001"/>
    </geometry>
    <material name="silver"/>
  </visual>
  <collision>
    <origin xyz="0.130196 -0.070181 -0.0387" rpy="0 0 0"/>
    <geometry>
      <mesh filename="file://$(find prjct_spider_bot_description)/meshes/femur_FR_1.stl" scale="0.001 0.001 0.001"/>
    </geometry>
  </collision>
</link>

<link name="tibia_FR_1">
  <inertial>
    <origin xyz="0.015552752309943102 0.02595204711365401 -0.04435033820279627" rpy="0 0 0"/>
    <mass value="0.856718844269578"/>
    <inertia ixx="0.001697" iyy="0.001665" izz="0.000146" ixy="-1.3e-05" iyz="6.5e-05" ixz="-7.6e-05"/>
  </inertial>
  <visual>
    <origin xyz="0.179439 -0.119425 -0.02004" rpy="0 0 0"/>
    <geometry>
      <mesh filename="file://$(find prjct_spider_bot_description)/meshes/tibia_FR_1.stl" scale="0.001 0.001 0.001"/>
    </geometry>
    <material name="silver"/>
  </visual>
  <collision>
    <origin xyz="0.179439 -0.119425 -0.02004" rpy="0 0 0"/>
    <geometry>
      <mesh filename="file://$(find prjct_spider_bot_description)/meshes/tibia_FR_1.stl" scale="0.001 0.001 0.001"/>
    </geometry>
  </collision>
</link>

<link name="coxa_BR_1">
  <inertial>
    <origin xyz="0.029189002811872485 0.028011587314280273 -0.025161452378790708" rpy="0 0 0"/>
    <mass value="0.5326447248518721"/>
    <inertia ixx="0.000276" iyy="0.00026" izz="0.000188" ixy="-2.9e-05" iyz="2e-06" ixz="-1e-05"/>
  </inertial>
  <visual>
    <origin xyz="-0.0549 -0.0542 -0.0528" rpy="0 0 0"/>
    <geometry>
      <mesh filename="file://$(find prjct_spider_bot_description)/meshes/coxa_BR_1.stl" scale="0.001 0.001 0.001"/>
    </geometry>
    <material name="silver"/>
  </visual>
  <collision>
    <origin xyz="-0.0549 -0.0542 -0.0528" rpy="0 0 0"/>
    <geometry>
      <mesh filename="file://$(find prjct_spider_bot_description)/meshes/coxa_BR_1.stl" scale="0.001 0.001 0.001"/>
    </geometry>
  </collision>
</link>

<link name="femur_BR_1">
  <inertial>
    <origin xyz="0.04487919855016356 0.0065592835375610226 -0.003537197394316516" rpy="0 0 0"/>
    <mass value="0.3037238401732045"/>
    <inertia ixx="0.000169" iyy="0.000169" izz="0.000293" ixy="3.2e-05" iyz="1.9e-05" ixz="1.9e-05"/>
  </inertial>
  <visual>
    <origin xyz="-0.070881 -0.109496 -0.0387" rpy="0 0 0"/>
    <geometry>
      <mesh filename="file://$(find prjct_spider_bot_description)/meshes/femur_BR_1.stl" scale="0.001 0.001 0.001"/>
    </geometry>
    <material name="silver"/>
  </visual>
  <collision>
    <origin xyz="-0.070881 -0.109496 -0.0387" rpy="0 0 0"/>
    <geometry>
      <mesh filename="file://$(find prjct_spider_bot_description)/meshes/femur_BR_1.stl" scale="0.001 0.001 0.001"/>
    </geometry>
  </collision>
</link>

<link name="tibia_BR_1">
  <inertial>
    <origin xyz="0.0259525822614622 -0.015553287457752918 -0.04435033820279581" rpy="0 0 0"/>
    <mass value="0.856718844269578"/>
    <inertia ixx="0.001665" iyy="0.001697" izz="0.000146" ixy="1.3e-05" iyz="7.6e-05" ixz="6.5e-05"/>
  </inertial>
  <visual>
    <origin xyz="-0.120124 -0.15874 -0.02004" rpy="0 0 0"/>
    <geometry>
      <mesh filename="file://$(find prjct_spider_bot_description)/meshes/tibia_BR_1.stl" scale="0.001 0.001 0.001"/>
    </geometry>
    <material name="silver"/>
  </visual>
  <collision>
    <origin xyz="-0.120124 -0.15874 -0.02004" rpy="0 0 0"/>
    <geometry>
      <mesh filename="file://$(find prjct_spider_bot_description)/meshes/tibia_BR_1.stl" scale="0.001 0.001 0.001"/>
    </geometry>
  </collision>
</link>

<link name="coxa_FL_1">
  <inertial>
    <origin xyz="-0.029189002811871978 -0.028011587314280176 -0.025161452378790538" rpy="0 0 0"/>
    <mass value="0.5326447248518721"/>
    <inertia ixx="0.000276" iyy="0.00026" izz="0.000188" ixy="-2.9e-05" iyz="-2e-06" ixz="1e-05"/>
  </inertial>
  <visual>
    <origin xyz="0.0749 0.0942 -0.0528" rpy="0 0 0"/>
    <geometry>
      <mesh filename="file://$(find prjct_spider_bot_description)/meshes/coxa_FL_1.stl" scale="0.001 0.001 0.001"/>
    </geometry>
    <material name="silver"/>
  </visual>
  <collision>
    <origin xyz="0.0749 0.0942 -0.0528" rpy="0 0 0"/>
    <geometry>
      <mesh filename="file://$(find prjct_spider_bot_description)/meshes/coxa_FL_1.stl" scale="0.001 0.001 0.001"/>
    </geometry>
  </collision>
</link>

<link name="femur_FL_1">
  <inertial>
    <origin xyz="-0.0448791985501633 -0.006559283537560828 -0.0035371973943163076" rpy="0 0 0"/>
    <mass value="0.3037238401732045"/>
    <inertia ixx="0.000169" iyy="0.000169" izz="0.000293" ixy="3.2e-05" iyz="-1.9e-05" ixz="-1.9e-05"/>
  </inertial>
  <visual>
    <origin xyz="0.090881 0.149496 -0.0387" rpy="0 0 0"/>
    <geometry>
      <mesh filename="file://$(find prjct_spider_bot_description)/meshes/femur_FL_1.stl" scale="0.001 0.001 0.001"/>
    </geometry>
    <material name="silver"/>
  </visual>
  <collision>
    <origin xyz="0.090881 0.149496 -0.0387" rpy="0 0 0"/>
    <geometry>
      <mesh filename="file://$(find prjct_spider_bot_description)/meshes/femur_FL_1.stl" scale="0.001 0.001 0.001"/>
    </geometry>
  </collision>
</link>

<link name="tibia_FL_1">
  <inertial>
    <origin xyz="-0.025952582261461687 0.015553287457753001 -0.0443503382027953" rpy="0 0 0"/>
    <mass value="0.856718844269578"/>
    <inertia ixx="0.001665" iyy="0.001697" izz="0.000146" ixy="1.3e-05" iyz="-7.6e-05" ixz="-6.5e-05"/>
  </inertial>
  <visual>
    <origin xyz="0.140124 0.19874 -0.02004" rpy="0 0 0"/>
    <geometry>
      <mesh filename="file://$(find prjct_spider_bot_description)/meshes/tibia_FL_1.stl" scale="0.001 0.001 0.001"/>
    </geometry>
    <material name="silver"/>
  </visual>
  <collision>
    <origin xyz="0.140124 0.19874 -0.02004" rpy="0 0 0"/>
    <geometry>
      <mesh filename="file://$(find prjct_spider_bot_description)/meshes/tibia_FL_1.stl" scale="0.001 0.001 0.001"/>
    </geometry>
  </collision>
</link>

<link name="coxa_BL_1">
  <inertial>
    <origin xyz="0.030448520904464337 -0.026637064512584144 -0.02516145237879068" rpy="0 0 0"/>
    <mass value="0.5326447248518721"/>
    <inertia ixx="0.000255" iyy="0.000281" izz="0.000188" ixy="2.7e-05" iyz="1e-05" ixz="1e-06"/>
  </inertial>
  <visual>
    <origin xyz="-0.0549 0.0942 -0.0528" rpy="0 0 0"/>
    <geometry>
      <mesh filename="file://$(find prjct_spider_bot_description)/meshes/coxa_BL_1.stl" scale="0.001 0.001 0.001"/>
    </geometry>
    <material name="silver"/>
  </visual>
  <collision>
    <origin xyz="-0.0549 0.0942 -0.0528" rpy="0 0 0"/>
    <geometry>
      <mesh filename="file://$(find prjct_spider_bot_description)/meshes/coxa_BL_1.stl" scale="0.001 0.001 0.001"/>
    </geometry>
  </collision>
</link>

<link name="femur_BL_1">
  <inertial>
    <origin xyz="0.010445758234201477 -0.04413706930762948 -0.0035371973943158427" rpy="0 0 0"/>
    <mass value="0.3037238401732045"/>
    <inertia ixx="0.000174" iyy="0.000163" izz="0.000293" ixy="-3.2e-05" iyz="-1.7e-05" ixz="2e-05"/>
  </inertial>
  <visual>
    <origin xyz="-0.111378 0.105301 -0.0387" rpy="0 0 0"/>
    <geometry>
      <mesh filename="file://$(find prjct_spider_bot_description)/meshes/femur_BL_1.stl" scale="0.001 0.001 0.001"/>
    </geometry>
    <material name="silver"/>
  </visual>
  <collision>
    <origin xyz="-0.111378 0.105301 -0.0387" rpy="0 0 0"/>
    <geometry>
      <mesh filename="file://$(find prjct_spider_bot_description)/meshes/femur_BL_1.stl" scale="0.001 0.001 0.001"/>
    </geometry>
  </collision>
</link>

<link name="tibia_BL_1">
  <inertial>
    <origin xyz="-0.013231809099896463 -0.02720943017943131 -0.04435033820279533" rpy="0 0 0"/>
    <mass value="0.856718844269578"/>
    <inertia ixx="0.001699" iyy="0.001663" izz="0.000146" ixy="-1e-05" iyz="-5.8e-05" ixz="8.1e-05"/>
  </inertial>
  <visual>
    <origin xyz="-0.164726 0.150065 -0.02004" rpy="0 0 0"/>
    <geometry>
      <mesh filename="file://$(find prjct_spider_bot_description)/meshes/tibia_BL_1.stl" scale="0.001 0.001 0.001"/>
    </geometry>
    <material name="silver"/>
  </visual>
  <collision>
    <origin xyz="-0.164726 0.150065 -0.02004" rpy="0 0 0"/>
    <geometry>
      <mesh filename="file://$(find prjct_spider_bot_description)/meshes/tibia_BL_1.stl" scale="0.001 0.001 0.001"/>
    </geometry>
  </collision>
</link>

<joint name="J_Lidar" type="continuous">
  <origin xyz="-0.069407 -0.019459 0.0877" rpy="0 0 0"/>
  <parent link="base_link"/>
  <child link="lidar_1"/>
  <axis xyz="0.0 0.0 -1.0"/>
</joint>

<joint name="J_IMU" type="fixed">
  <origin xyz="0.01 -0.02 0.0877" rpy="0 0 0"/>
  <parent link="base_link"/>
  <child link="imu_1"/>
</joint>

<joint name="J_camstand" type="fixed">
  <origin xyz="0.064 -0.02 0.0877" rpy="0 0 0"/>
  <parent link="base_link"/>
  <child link="camera_stand_1"/>
</joint>

<joint name="J_Camera" type="fixed">
  <origin xyz="-0.002775 0.0 0.077" rpy="0 0 0"/>
  <parent link="camera_stand_1"/>
  <child link="camera_1"/>
</joint>

<joint name="J_Coxa_FR" type="revolute">
  <origin xyz="-0.0749 0.0542 0.0528" rpy="0 0 0"/>
  <parent link="base_link"/>
  <child link="coxa_FR_1"/>
  <axis xyz="0.0 0.0 1.0"/>
  <limit upper="1.308997" lower="-1.308997" effort="100" velocity="100"/>
</joint>

<joint name="J_Femur_FR" type="revolute">
  <origin xyz="-0.055296 0.015981 -0.0141" rpy="0 0 0"/>
  <parent link="coxa_FR_1"/>
  <child link="femur_FR_1"/>
  <axis xyz="-0.707107 -0.707107 -0.0"/>
  <limit upper="0.785398" lower="-1.570796" effort="100" velocity="100"/>
</joint>

<joint name="J_Tibia_FR" type="revolute">
  <origin xyz="-0.049243 0.049244 -0.01866" rpy="0 0 0"/>
  <parent link="femur_FR_1"/>
  <child link="tibia_FR_1"/>
  <axis xyz="0.707107 0.707107 -0.0"/>
  <limit upper="1.570796" lower="-1.308997" effort="100" velocity="100"/>
</joint>

<joint name="J_Coxa_BR" type="revolute">
  <origin xyz="0.0549 0.0542 0.0528" rpy="0 0 0"/>
  <parent link="base_link"/>
  <child link="coxa_BR_1"/>
  <axis xyz="0.0 0.0 1.0"/>
  <limit upper="1.308997" lower="-1.308997" effort="100" velocity="100"/>
</joint>

<joint name="J_Femur_BR" type="revolute">
  <origin xyz="0.015981 0.055296 -0.0141" rpy="0 0 0"/>
  <parent link="coxa_BR_1"/>
  <child link="femur_BR_1"/>
  <axis xyz="-0.707107 0.707107 -0.0"/>
  <limit upper="0.785398" lower="-1.570796" effort="100" velocity="100"/>
</joint>

<joint name="J_Tibia_BR" type="revolute">
  <origin xyz="0.049243 0.049244 -0.01866" rpy="0 0 0"/>
  <parent link="femur_BR_1"/>
  <child link="tibia_BR_1"/>
  <axis xyz="0.707107 -0.707107 0.0"/>
  <limit upper="1.570796" lower="-1.308997" effort="100" velocity="100"/>
</joint>

<joint name="J_Coxa_FL" type="revolute">
  <origin xyz="-0.0749 -0.0942 0.0528" rpy="0 0 0"/>
  <parent link="base_link"/>
  <child link="coxa_FL_1"/>
  <axis xyz="0.0 0.0 1.0"/>
  <limit upper="1.570796" lower="-1.047198" effort="100" velocity="100"/>
</joint>

<joint name="J_Femur_FL" type="revolute">
  <origin xyz="-0.015981 -0.055296 -0.0141" rpy="0 0 0"/>
  <parent link="coxa_FL_1"/>
  <child link="femur_FL_1"/>
  <axis xyz="0.707107 -0.707107 -0.0"/>
  <limit upper="0.785398" lower="-1.570796" effort="100" velocity="100"/>
</joint>

<joint name="J_Tibia_FL" type="revolute">
  <origin xyz="-0.049243 -0.049244 -0.01866" rpy="0 0 0"/>
  <parent link="femur_FL_1"/>
  <child link="tibia_FL_1"/>
  <axis xyz="-0.707107 0.707107 0.0"/>
  <limit upper="1.570796" lower="-1.308997" effort="100" velocity="100"/>
</joint>

<joint name="J_Coxa_BL" type="revolute">
  <origin xyz="0.0549 -0.0942 0.0528" rpy="0 0 0"/>
  <parent link="base_link"/>
  <child link="coxa_BL_1"/>
  <axis xyz="0.0 0.0 1.0"/>
  <limit upper="1.22173" lower="-1.396263" effort="100" velocity="100"/>
</joint>

<joint name="J_Femur_BL" type="revolute">
  <origin xyz="0.056478 -0.011101 -0.0141" rpy="0 0 0"/>
  <parent link="coxa_BL_1"/>
  <child link="femur_BL_1"/>
  <axis xyz="0.642788 0.766044 -0.0"/>
  <limit upper="0.785398" lower="-1.570796" effort="100" velocity="100"/>
</joint>

<joint name="J_Tibia_BL" type="revolute">
  <origin xyz="0.053348 -0.044764 -0.01866" rpy="0 0 0"/>
  <parent link="femur_BL_1"/>
  <child link="tibia_BL_1"/>
  <axis xyz="-0.642788 -0.766044 0.0"/>
  <limit upper="1.570796" lower="-1.308997" effort="100" velocity="100"/>
</joint>

</robot>
