<?xml version="1.0" ?>
<robot name="spyderr" xmlns:xacro="http://www.ros.org/wiki/xacro">

<xacro:include filename="$(find spyderr_description)/urdf/materials.xacro" />
<xacro:include filename="$(find spyderr_description)/urdf/spyderr.ros2control" />
<xacro:include filename="$(find spyderr_description)/urdf/spyderr.gazebo" />
<link name="base_link">
  <inertial>
    <origin xyz="-0.011634383299055345 -0.020012327327441907 0.04021488449284461" rpy="0 0 0"/>
    <mass value="5.582430267110478"/>
    <inertia ixx="0.022303" iyy="0.019413" izz="0.030673" ixy="-6e-06" iyz="4e-06" ixz="0.000124"/>
  </inertial>
  <visual>
    <origin xyz="0 0 0" rpy="0 0 0"/>
    <geometry>
      <mesh filename="file://$(find spyderr_description)/meshes/base_link.stl" scale="0.001 0.001 0.001"/>
    </geometry>
    <material name="silver"/>
  </visual>
  <collision>
    <origin xyz="0 0 0" rpy="0 0 0"/>
    <geometry>
      <mesh filename="file://$(find spyderr_description)/meshes/base_link.stl" scale="0.001 0.001 0.001"/>
    </geometry>
  </collision>
</link>

<link name="coxa_FR_1">
  <inertial>
    <origin xyz="-0.028011122462089824 0.029189467664063093 -0.025661452378790764" rpy="0 0 0"/>
    <mass value="0.5326447248518721"/>
    <inertia ixx="0.00026" iyy="0.000276" izz="0.000188" ixy="2.9e-05" iyz="-1e-05" ixz="-2e-06"/>
  </inertial>
  <visual>
    <origin xyz="0.0749 -0.0542 -0.0528" rpy="0 0 0"/>
    <geometry>
      <mesh filename="file://$(find spyderr_description)/meshes/coxa_FR_1.stl" scale="0.001 0.001 0.001"/>
    </geometry>
    <material name="silver"/>
  </visual>
  <collision>
    <origin xyz="0.0749 -0.0542 -0.0528" rpy="0 0 0"/>
    <geometry>
      <mesh filename="file://$(find spyderr_description)/meshes/coxa_FR_1.stl" scale="0.001 0.001 0.001"/>
    </geometry>
  </collision>
</link>

<link name="femur_FR_1">
  <inertial>
    <origin xyz="-0.022308199277599444 0.09228828281012573 -0.028037197394316607" rpy="0 0 0"/>
    <mass value="0.3037238401732045"/>
    <inertia ixx="0.000169" iyy="0.000169" izz="0.000293" ixy="-3.2e-05" iyz="1.9e-05" ixz="-1.9e-05"/>
  </inertial>
  <visual>
    <origin xyz="0.113987 -0.023232 -0.0627" rpy="0 0 0"/>
    <geometry>
      <mesh filename="file://$(find spyderr_description)/meshes/femur_FR_1.stl" scale="0.001 0.001 0.001"/>
    </geometry>
    <material name="silver"/>
  </visual>
  <collision>
    <origin xyz="0.113987 -0.023232 -0.0627" rpy="0 0 0"/>
    <geometry>
      <mesh filename="file://$(find spyderr_description)/meshes/femur_FR_1.stl" scale="0.001 0.001 0.001"/>
    </geometry>
  </collision>
</link>

<link name="tibia_FR_1">
  <inertial>
    <origin xyz="0.06983981832712044 -0.04072388686916903 0.11930466179720378" rpy="0 0 0"/>
    <mass value="0.856718844269578"/>
    <inertia ixx="0.001697" iyy="0.001665" izz="0.000146" ixy="-1.3e-05" iyz="6.5e-05" ixz="-7.6e-05"/>
  </inertial>
  <visual>
    <origin xyz="0.23362 -0.186207 0.144115" rpy="0 0 0"/>
    <geometry>
      <mesh filename="file://$(find spyderr_description)/meshes/tibia_FR_1.stl" scale="0.001 0.001 0.001"/>
    </geometry>
    <material name="silver"/>
  </visual>
  <collision>
    <origin xyz="0.23362 -0.186207 0.144115" rpy="0 0 0"/>
    <geometry>
      <mesh filename="file://$(find spyderr_description)/meshes/tibia_FR_1.stl" scale="0.001 0.001 0.001"/>
    </geometry>
  </collision>
</link>

<link name="coxa_BR_1">
  <inertial>
    <origin xyz="0.02918900281187222 0.028011587314280717 -0.025661452378790736" rpy="0 0 0"/>
    <mass value="0.5326447248518721"/>
    <inertia ixx="0.000276" iyy="0.00026" izz="0.000188" ixy="-2.9e-05" iyz="2e-06" ixz="-1e-05"/>
  </inertial>
  <visual>
    <origin xyz="-0.0549 -0.0542 -0.0528" rpy="0 0 0"/>
    <geometry>
      <mesh filename="file://$(find spyderr_description)/meshes/coxa_BR_1.stl" scale="0.001 0.001 0.001"/>
    </geometry>
    <material name="silver"/>
  </visual>
  <collision>
    <origin xyz="-0.0549 -0.0542 -0.0528" rpy="0 0 0"/>
    <geometry>
      <mesh filename="file://$(find spyderr_description)/meshes/coxa_BR_1.stl" scale="0.001 0.001 0.001"/>
    </geometry>
  </collision>
</link>

<link name="femur_BR_1">
  <inertial>
    <origin xyz="-0.0771502480592433 0.13679673014696808 -0.028037197394316524" rpy="0 0 0"/>
    <mass value="0.3037238401732045"/>
    <inertia ixx="0.000169" iyy="0.000169" izz="0.000293" ixy="3.2e-05" iyz="1.9e-05" ixz="1.9e-05"/>
  </inertial>
  <visual>
    <origin xyz="-0.193264 0.021095 -0.0627" rpy="0 0 0"/>
    <geometry>
      <mesh filename="file://$(find spyderr_description)/meshes/femur_BR_1.stl" scale="0.001 0.001 0.001"/>
    </geometry>
    <material name="silver"/>
  </visual>
  <collision>
    <origin xyz="-0.193264 0.021095 -0.0627" rpy="0 0 0"/>
    <geometry>
      <mesh filename="file://$(find spyderr_description)/meshes/femur_BR_1.stl" scale="0.001 0.001 0.001"/>
    </geometry>
  </collision>
</link>

<link name="tibia_BR_1">
  <inertial>
    <origin xyz="-0.07159486434794465 -0.10141884084834538 -0.18156633820279572" rpy="0 0 0"/>
    <mass value="0.856718844269578"/>
    <inertia ixx="0.001665" iyy="0.001697" izz="0.000146" ixy="1.3e-05" iyz="7.6e-05" ixz="6.5e-05"/>
  </inertial>
  <visual>
    <origin xyz="-0.218025 -0.244252 -0.156756" rpy="0 0 0"/>
    <geometry>
      <mesh filename="file://$(find spyderr_description)/meshes/tibia_BR_1.stl" scale="0.001 0.001 0.001"/>
    </geometry>
    <material name="silver"/>
  </visual>
  <collision>
    <origin xyz="-0.218025 -0.244252 -0.156756" rpy="0 0 0"/>
    <geometry>
      <mesh filename="file://$(find spyderr_description)/meshes/tibia_BR_1.stl" scale="0.001 0.001 0.001"/>
    </geometry>
  </collision>
</link>

<link name="coxa_FL_1">
  <inertial>
    <origin xyz="-0.02918900281187209 -0.028011587314280648 -0.02566145237879071" rpy="0 0 0"/>
    <mass value="0.5326447248518721"/>
    <inertia ixx="0.000276" iyy="0.00026" izz="0.000188" ixy="-2.9e-05" iyz="-2e-06" ixz="1e-05"/>
  </inertial>
  <visual>
    <origin xyz="0.0749 0.0942 -0.0528" rpy="0 0 0"/>
    <geometry>
      <mesh filename="file://$(find spyderr_description)/meshes/coxa_FL_1.stl" scale="0.001 0.001 0.001"/>
    </geometry>
    <material name="silver"/>
  </visual>
  <collision>
    <origin xyz="0.0749 0.0942 -0.0528" rpy="0 0 0"/>
    <geometry>
      <mesh filename="file://$(find spyderr_description)/meshes/coxa_FL_1.stl" scale="0.001 0.001 0.001"/>
    </geometry>
  </collision>
</link>

<link name="femur_FL_1">
  <inertial>
    <origin xyz="-0.22036675194075658 -0.20554973014696815 -0.02803719739431651" rpy="0 0 0"/>
    <mass value="0.3037238401732045"/>
    <inertia ixx="0.000169" iyy="0.000169" izz="0.000293" ixy="3.2e-05" iyz="-1.9e-05" ixz="-1.9e-05"/>
  </inertial>
  <visual>
    <origin xyz="-0.084253 -0.049848 -0.0627" rpy="0 0 0"/>
    <geometry>
      <mesh filename="file://$(find spyderr_description)/meshes/femur_FL_1.stl" scale="0.001 0.001 0.001"/>
    </geometry>
    <material name="silver"/>
  </visual>
  <collision>
    <origin xyz="-0.084253 -0.049848 -0.0627" rpy="0 0 0"/>
    <geometry>
      <mesh filename="file://$(find spyderr_description)/meshes/femur_FL_1.stl" scale="0.001 0.001 0.001"/>
    </geometry>
  </collision>
</link>

<link name="tibia_FL_1">
  <inertial>
    <origin xyz="-0.18368113565205535 -0.15385715915165465 0.07514566179720432" rpy="0 0 0"/>
    <mass value="0.856718844269578"/>
    <inertia ixx="0.001665" iyy="0.001697" izz="0.000146" ixy="1.3e-05" iyz="-7.6e-05" ixz="-6.5e-05"/>
  </inertial>
  <visual>
    <origin xyz="-0.017251 0.028976 0.099956" rpy="0 0 0"/>
    <geometry>
      <mesh filename="file://$(find spyderr_description)/meshes/tibia_FL_1.stl" scale="0.001 0.001 0.001"/>
    </geometry>
    <material name="silver"/>
  </visual>
  <collision>
    <origin xyz="-0.017251 0.028976 0.099956" rpy="0 0 0"/>
    <geometry>
      <mesh filename="file://$(find spyderr_description)/meshes/tibia_FL_1.stl" scale="0.001 0.001 0.001"/>
    </geometry>
  </collision>
</link>

<link name="coxa_BL_1">
  <inertial>
    <origin xyz="0.02801112246208972 -0.02918946766406294 -0.025661452378790733" rpy="0 0 0"/>
    <mass value="0.5326447248518721"/>
    <inertia ixx="0.00026" iyy="0.000276" izz="0.000188" ixy="2.9e-05" iyz="1e-05" ixz="2e-06"/>
  </inertial>
  <visual>
    <origin xyz="-0.0549 0.0942 -0.0528" rpy="0 0 0"/>
    <geometry>
      <mesh filename="file://$(find spyderr_description)/meshes/coxa_BL_1.stl" scale="0.001 0.001 0.001"/>
    </geometry>
    <material name="silver"/>
  </visual>
  <collision>
    <origin xyz="-0.0549 0.0942 -0.0528" rpy="0 0 0"/>
    <geometry>
      <mesh filename="file://$(find spyderr_description)/meshes/coxa_BL_1.stl" scale="0.001 0.001 0.001"/>
    </geometry>
  </collision>
</link>

<link name="femur_BL_1">
  <inertial>
    <origin xyz="0.32028581868537026 -0.05003066340235417 -0.02803719739431655" rpy="0 0 0"/>
    <mass value="0.3037238401732045"/>
    <inertia ixx="0.000169" iyy="0.000169" izz="0.000293" ixy="-3.2e-05" iyz="-1.9e-05" ixz="1.9e-05"/>
  </inertial>
  <visual>
    <origin xyz="0.203531 0.10503 -0.0627" rpy="0 0 0"/>
    <geometry>
      <mesh filename="file://$(find spyderr_description)/meshes/femur_BL_1.stl" scale="0.001 0.001 0.001"/>
    </geometry>
    <material name="silver"/>
  </visual>
  <collision>
    <origin xyz="0.203531 0.10503 -0.0627" rpy="0 0 0"/>
    <geometry>
      <mesh filename="file://$(find spyderr_description)/meshes/femur_BL_1.stl" scale="0.001 0.001 0.001"/>
    </geometry>
  </collision>
</link>

<link name="tibia_BL_1">
  <inertial>
    <origin xyz="0.12266080108065015 -0.1517774937230599 -0.22618533820279574" rpy="0 0 0"/>
    <mass value="0.856718844269578"/>
    <inertia ixx="0.001697" iyy="0.001665" izz="0.000146" ixy="-1.3e-05" iyz="-6.5e-05" ixz="7.6e-05"/>
  </inertial>
  <visual>
    <origin xyz="-0.021579 0.033246 -0.201375" rpy="0 0 0"/>
    <geometry>
      <mesh filename="file://$(find spyderr_description)/meshes/tibia_BL_1.stl" scale="0.001 0.001 0.001"/>
    </geometry>
    <material name="silver"/>
  </visual>
  <collision>
    <origin xyz="-0.021579 0.033246 -0.201375" rpy="0 0 0"/>
    <geometry>
      <mesh filename="file://$(find spyderr_description)/meshes/tibia_BL_1.stl" scale="0.001 0.001 0.001"/>
    </geometry>
  </collision>
</link>

<link name="camera_stand_1">
  <inertial>
    <origin xyz="0.002322519957098118 -0.006000468557076734 0.0390749353327329" rpy="0 0 0"/>
    <mass value="0.28621405783156734"/>
    <inertia ixx="0.000356" iyy="0.000274" izz="0.000106" ixy="-0.0" iyz="-0.0" ixz="-0.0"/>
  </inertial>
  <visual>
    <origin xyz="-0.064 0.02 -0.0877" rpy="0 0 0"/>
    <geometry>
      <mesh filename="file://$(find spyderr_description)/meshes/camera_stand_1.stl" scale="0.001 0.001 0.001"/>
    </geometry>
    <material name="silver"/>
  </visual>
  <collision>
    <origin xyz="-0.064 0.02 -0.0877" rpy="0 0 0"/>
    <geometry>
      <mesh filename="file://$(find spyderr_description)/meshes/camera_stand_1.stl" scale="0.001 0.001 0.001"/>
    </geometry>
  </collision>
</link>

<link name="camera_1">
  <inertial>
    <origin xyz="0.0008434977883624364 5.831530578721475e-05 0.013401911513465398" rpy="0 0 0"/>
    <mass value="0.04133715258262728"/>
    <inertia ixx="4.5e-05" iyy="8e-06" izz="4.5e-05" ixy="0.0" iyz="0.0" ixz="-0.0"/>
  </inertial>
  <visual>
    <origin xyz="-0.061225 0.026 -0.1647" rpy="0 0 0"/>
    <geometry>
      <mesh filename="file://$(find spyderr_description)/meshes/camera_1.stl" scale="0.001 0.001 0.001"/>
    </geometry>
    <material name="silver"/>
  </visual>
  <collision>
    <origin xyz="-0.061225 0.026 -0.1647" rpy="0 0 0"/>
    <geometry>
      <mesh filename="file://$(find spyderr_description)/meshes/camera_1.stl" scale="0.001 0.001 0.001"/>
    </geometry>
  </collision>
</link>

<link name="lidar_1">
  <inertial>
    <origin xyz="1.1999484417213324e-07 7.55530585108688e-08 0.009521070328133568" rpy="0 0 0"/>
    <mass value="0.6521818172175858"/>
    <inertia ixx="0.000253" iyy="0.000253" izz="0.000465" ixy="-0.0" iyz="-0.0" ixz="-0.0"/>
  </inertial>
  <visual>
    <origin xyz="0.069407 0.019459 -0.0877" rpy="0 0 0"/>
    <geometry>
      <mesh filename="file://$(find spyderr_description)/meshes/lidar_1.stl" scale="0.001 0.001 0.001"/>
    </geometry>
    <material name="silver"/>
  </visual>
  <collision>
    <origin xyz="0.069407 0.019459 -0.0877" rpy="0 0 0"/>
    <geometry>
      <mesh filename="file://$(find spyderr_description)/meshes/lidar_1.stl" scale="0.001 0.001 0.001"/>
    </geometry>
  </collision>
</link>

<link name="imu_1">
  <inertial>
    <origin xyz="6.730727086790012e-16 -4.6485218993877475e-07 0.00250000000000003" rpy="0 0 0"/>
    <mass value="0.047099999999999996"/>
    <inertia ixx="6e-06" iyy="4e-06" izz="1e-05" ixy="0.0" iyz="0.0" ixz="0.0"/>
  </inertial>
  <visual>
    <origin xyz="-0.01 0.02 -0.0877" rpy="0 0 0"/>
    <geometry>
      <mesh filename="file://$(find spyderr_description)/meshes/imu_1.stl" scale="0.001 0.001 0.001"/>
    </geometry>
    <material name="silver"/>
  </visual>
  <collision>
    <origin xyz="-0.01 0.02 -0.0877" rpy="0 0 0"/>
    <geometry>
      <mesh filename="file://$(find spyderr_description)/meshes/imu_1.stl" scale="0.001 0.001 0.001"/>
    </geometry>
  </collision>
</link>

<joint name="joint1" type="revolute">
  <origin xyz="-0.0749 0.0542 0.0528" rpy="0 0 0"/>
  <parent link="base_link"/>
  <child link="coxa_FR_1"/>
  <axis xyz="0.0 0.0 1.0"/>
  <limit upper="2.356194" lower="-0.785398" effort="100" velocity="100"/>
</joint>

<joint name="joint2" type="revolute">
  <origin xyz="-0.039087 -0.030968 0.0099" rpy="0 0 0"/>
  <parent link="coxa_FR_1"/>
  <child link="femur_FR_1"/>
  <axis xyz="-0.707107 -0.707107 -0.0"/>
  <limit upper="1.570796" lower="-1.570796" effort="100" velocity="100"/>
</joint>

<joint name="joint3" type="revolute">
  <origin xyz="-0.119633 0.162975 -0.206815" rpy="0 0 0"/>
  <parent link="femur_FR_1"/>
  <child link="tibia_FR_1"/>
  <axis xyz="-0.707107 -0.707107 -0.0"/>
  <limit upper="1.570796" lower="-1.570796" effort="100" velocity="100"/>
</joint>

<joint name="joint4" type="revolute">
  <origin xyz="0.0549 0.0542 0.0528" rpy="0 0 0"/>
  <parent link="base_link"/>
  <child link="coxa_BR_1"/>
  <axis xyz="0.0 0.0 1.0"/>
  <limit upper="0.785398" lower="-2.356194" effort="100" velocity="100"/>
</joint>

<joint name="joint5" type="revolute">
  <origin xyz="0.138364 -0.075295 0.0099" rpy="0 0 0"/>
  <parent link="coxa_BR_1"/>
  <child link="femur_BR_1"/>
  <axis xyz="-0.707107 0.707107 -0.0"/>
  <limit upper="4.712389" lower="1.570796" effort="100" velocity="100"/>
</joint>

<joint name="joint6" type="revolute">
  <origin xyz="0.024761 0.265347 0.094056" rpy="0 0 0"/>
  <parent link="femur_BR_1"/>
  <child link="tibia_BR_1"/>
  <axis xyz="-0.707107 0.707107 -0.0"/>
  <limit upper="1.570796" lower="-1.570796" effort="100" velocity="100"/>
</joint>

<joint name="joint7" type="revolute">
  <origin xyz="-0.0749 -0.0942 0.0528" rpy="0 0 0"/>
  <parent link="base_link"/>
  <child link="coxa_FL_1"/>
  <axis xyz="0.0 0.0 1.0"/>
  <limit upper="3.926991" lower="0.785398" effort="100" velocity="100"/>
</joint>

<joint name="joint9" type="revolute">
  <origin xyz="0.159153 0.144048 0.0099" rpy="0 0 0"/>
  <parent link="coxa_FL_1"/>
  <child link="femur_FL_1"/>
  <axis xyz="0.707107 -0.707107 -0.0"/>
  <limit upper="1.570796" lower="-1.570796" effort="100" velocity="100"/>
</joint>

<joint name="joint10" type="revolute">
  <origin xyz="-0.067002 -0.078824 -0.162656" rpy="0 0 0"/>
  <parent link="femur_FL_1"/>
  <child link="tibia_FL_1"/>
  <axis xyz="0.707107 -0.707107 -0.0"/>
  <limit upper="1.570796" lower="-1.570796" effort="100" velocity="100"/>
</joint>

<joint name="joint11" type="revolute">
  <origin xyz="0.0549 -0.0942 0.0528" rpy="0 0 0"/>
  <parent link="base_link"/>
  <child link="coxa_BL_1"/>
  <axis xyz="0.0 0.0 1.0"/>
  <limit upper="-0.785398" lower="-3.926991" effort="100" velocity="100"/>
</joint>

<joint name="joint12" type="revolute">
  <origin xyz="-0.258431 -0.01083 0.0099" rpy="0 0 0"/>
  <parent link="coxa_BL_1"/>
  <child link="femur_BL_1"/>
  <axis xyz="0.707107 0.707107 -0.0"/>
  <limit upper="4.712389" lower="1.570796" effort="100" velocity="100"/>
</joint>

<joint name="joint13" type="revolute">
  <origin xyz="0.22511 0.071784 0.138675" rpy="0 0 0"/>
  <parent link="femur_BL_1"/>
  <child link="tibia_BL_1"/>
  <axis xyz="0.707107 0.707107 -0.0"/>
  <limit upper="1.570796" lower="-1.570796" effort="100" velocity="100"/>
</joint>

<joint name="joint14" type="fixed">
  <origin xyz="0.064 -0.02 0.0877" rpy="0 0 0"/>
  <parent link="base_link"/>
  <child link="camera_stand_1"/>
</joint>

<joint name="joint15" type="fixed">
  <origin xyz="-0.002775 -0.006 0.077" rpy="0 0 0"/>
  <parent link="camera_stand_1"/>
  <child link="camera_1"/>
</joint>

<joint name="joint16" type="continuous">
  <origin xyz="-0.069407 -0.019459 0.0877" rpy="0 0 0"/>
  <parent link="base_link"/>
  <child link="lidar_1"/>
  <axis xyz="0.0 0.0 -1.0"/>
</joint>

<joint name="joint17" type="fixed">
  <origin xyz="0.01 -0.02 0.0877" rpy="0 0 0"/>
  <parent link="base_link"/>
  <child link="imu_1"/>
</joint>

</robot>
